Workbook
Name ActiveDecisionQueueIDs: '[1]Lists & Controls'!$P$3:$P$150
Name ActiveDecisionQueueIDs: 'Lists & Controls'!$P$3:$P$150

Sheet 5-Minute Summary
A1: SLT Tracker — 5-Minute Executive Summary
A2: Purpose: a fast read of the workbook’s main topics, risk highlights, and executive action items as of Jul 22, 2026.
A3: Summary date | B3: =DATE(2026,7,22) -> 46225
A4: Story in Brief
A5: This workbook is a board-ready SLT action and decision tracker. The immediate management focus is six active action records, especially overdue compensation/HR items, critical ASP Go-Live readiness, CFO governance controls, and items requiring CEO/CFO escalation. The dashboards and board summaries show the same executive metrics, while the Action Register and Decision Queue hold the working detail. The Decision Register is structured for permanent records but does not yet contain logged decision details.
A7: Open Actions | C7: Overdue | E7: Critical Priority | G7: High Risk
A8: =COUNTIFS('Action Register'!$B:$B,"<>",'Action Register'!$G:$G,"<>Completed",'Action Register'!$T:$T,"ACTIVE") -> 29 | C8: {=SUMPRODUCT(('Action Register'!$B$5:$B$104<>"")*('Action Register'!$G$5:$G$104<>"Completed")*('Action Register'!$T$5:$T$104="ACTIVE")*(IFERROR(--'Action Register'!$F$5:$F$104,DATEVALUE('Action Register'!$F$5:$F$104))<$B$3))} -> 0 | E8: =COUNTIFS('Action Register'!$B:$B,"<>",'Action Register'!$H:$H,"Critical",'Action Register'!$T:$T,"ACTIVE") -> 0 | G8: =COUNTIFS('Action Register'!$B:$B,"<>",'Action Register'!$J:$J,"High",'Action Register'!$T:$T,"ACTIVE") -> 6
A9: Active, non-completed records | C9: Due before summary date | E9: Priority = Critical | G9: Risk Impact = High
A11: Escalations | C11: ASP Go-Live Items | E11: Active Decisions | G11: Logged Decisions
A12: =COUNTIFS('Action Register'!$B:$B,"<>",'Action Register'!$L:$L,"Yes",'Action Register'!$T:$T,"ACTIVE") -> 3 | C12: =COUNTIFS('Action Register'!$B:$B,"<>",'Action Register'!$K:$K,"ASP Go-Live",'Action Register'!$T:$T,"ACTIVE") -> 5 | E12: =COUNTIFS('Decision Queue_Bak'!$B:$B,"<>",'Decision Queue_Bak'!$W:$W,"ACTIVE") -> 3 | G12: =MAX(0,COUNTA('Decision Register_Bak'!$C:$C)-1) -> 2
A13: Escalation Required = Yes | C13: Strategic Objective = ASP Go-Live | E13: Decision Queue items with detail | G13: Decision summaries recorded
A15: Main Topics Covered
A16: Topic | B16: What it means | C16: Where to read | E16: # | F16: Highlight
A17: SLT action tracking | B17: The central register tracks owners, due dates, next actions, status, priority, risk, escalation, financial impact, and strategic alignment. | C17: Action Register | E17: 1 | F17: The active action set is small but executive-heavy: six open actions, five escalation flags, three high-risk items, and two critical-priority items.
A18: Board / SLT summary | B18: Board-ready snapshot of open, overdue, critical, high-risk, escalation, and ASP Go-Live items. | C18: Board Summary (2) | E18: 2 | F18: Gene owns two open actions and both overdue items; the compensation/wage item is already past due and needs status confirmation.
A19: Executive dashboard | B19: Owner and strategic-objective views that show where attention is concentrated. | C19: Executive Dashboard (2) | E19: 3 | F19: ASP Go-Live is the clearest strategic risk: it is critical, high-risk, escalated, financially material (>$250K), and requires cross-functional inputs.
A20: ASP Go-Live readiness | B20: A dedicated executive workstream for licensing, construction, operations readiness, HR, training, ERP, capital spend, customer transition, and risk register inputs. | C20: Action Register / Decision Queue | E20: 4 | F20: CFO Governance & Controls is also critical/high-risk/escalated and is intended to become a live control register.
A21: Governance & controls | B21: CFO-led visibility for DOA, contracts, AI governance, incident management, audit findings, grants, legal review, and controls. | C21: Action Register / Enhancement Log | E21: 5 | F21: The Decision Queue has two active CEO/CFO attention items: tracker governance structure due Jul 22 and separate ASP Go-Live executive section due Jul 24.
A22: Decision queue and register | B22: Pending decisions are queued for CEO/CFO/SLT alignment; the permanent decision log is prepared but not yet populated with real decision details. | C22: Decision Queue / Decision Register | E22: 6 | F22: There are duplicate Board Summary and Executive Dashboard sheets; the “(2)” versions appear cleaner and more board-readable than the older versions.
A23: Controls and dropdowns | B23: Standard lists define status, priority, risk, financial impact, decision type, workstream, and ASP readiness streams. | C23: Lists & Controls
A25: Action Items for You / Executive Reviewer
A26: Priority | B26: Action item | C26: Owner / source | D26: Timing | E26: Minute | F26: Read this | G26: Why
A27: 1 | B27: Confirm whether to adopt the enhanced tracker governance model, required fields, and dashboard structure. | C27: Decision Queue: DEC-0001 / Sandy | D27: 46225 | E27: 1 | F27: KPI tiles on this sheet | G27: Know the scale and urgency immediately.
A28: 2 | B28: Resolve overdue Gene-owned items, especially wage increase review and payroll advance policy follow-through. | C28: Action Register: SLT-0001, SLT-0002 / Gene | D28: Immediate | E28: 2 | F28: Top Highlights | G28: Understand the executive storyline.
A29: 3 | B29: Treat ASP Go-Live as a separate executive workstream and confirm owner, cadence, and readiness sub-stream reporting. | C29: Decision Queue: DEC-0002 / Maurizio | D29: 46227 | E29: 3 | F29: Action Items | G29: Decide what you need to approve, escalate, or ask for.
A30: 4 | B30: Review critical/high-risk escalations first: ASP Go-Live readiness, CFO Governance & Controls, and financial impact classification. | C30: Action Register: SLT-0003, SLT-0004, SLT-0005 | D30: Next SLT review | E30: 4 | F30: Board Summary (2) | G30: Review board-facing items requiring attention.
A31: 5 | B31: Require missing financial materiality details where marked Unknown / TBD before board discussion. | C31: Action Register / Decision Queue | D31: Before board review | E31: 5 | F31: Decision Queue | G31: Confirm what needs CEO/CFO/SLT direction.
A32: 6 | B32: After decisions are made, move outcomes into the permanent Decision Register with decision maker, rationale, follow-up owner, and due date. | C32: Decision Register | D32: After each decision
A33: 7 | B33: Consolidate duplicate dashboard/summary versions so the workbook has one authoritative board view. | C33: Board Summary / Executive Dashboard | D33: Before circulation
A35: Important workbook notes
A36: 1
A37: 2
A38: 3

Sheet Board Summary (2)
A1: SLT Action Tracker - Board Summary
A2: Prepared for executive review. Focus areas: overdue decisions, critical/high-risk items, escalation points, ASP Go-Live readiness, and governance controls.
A4: Prepared for | B4: SLT / Board Review | D4: Prepared by | G4: Version | J4: Date | K4: 46219
A6: Open Actions | C6: Overdue | E6: Critical Priority | G6: High Risk | I6: Escalations | J6: ASP Go-Live Items
A7: ='Executive Dashboard'!A5 -> 29 | C7: ='Executive Dashboard'!C5 -> 10 | E7: ='Executive Dashboard'!F5 -> 0 | G7: ='Executive Dashboard'!K5 -> 6 | I7: 5 | J7: 1
A10: Items Requiring Executive Attention
A11: ID | B11: Item | C11: Owner | D11: Due Date | E11: Status | F11: Priority | G11: Risk | H11: Escalation | I11: Strategic Objective | J11: Board Note
A12: {=_xlfn.LET( _xlpm.ids,'Action Register'!$A$5:$A$104, _xlpm.items,'Action Register'!$B$5:$B$104, _xlpm.owners,'Action Register'!$D$5:$D$104, _xlpm.due,'Action Register'!$F$5:$F$104, _xlpm.dueNum,IFERROR(--_xlpm.due,DATEVALUE(_xlpm.due)), _xlpm.status,'Action Register'!$G$5:$G$104, _xlpm.pri,'Action Register'!$H$5:$H$104, _xlpm.risk,'Action Register'!$J$5:$J$104, _xlpm.obj,'Action Register'!$K$5:$K$104, _xlpm.esc,'Action Register'!$L$5:$L$104, _xlpm.note,'Action Register'!$P$5:$P$104, _xlpm.active,'Action Register'!$T$5:$T$104, _xlpm.include,(_xlpm.items<>"")*(_xlpm.active="ACTIVE")*((_xlpm.pri="Critical")+(_xlpm.pri="High")+(_xlpm.risk="High")+(_xlpm.esc="Yes")), _xlpm.data,CHOOSE({1,2,3,4,5,6,7,8,9,10},_xlpm.ids,_xlpm.items,_xlpm.owners,_xlpm.due,_xlpm.status,_xlpm.pri,_xlpm.risk,_xlpm.esc,_xlpm.obj,_xlpm.note), _xlpm.prioritySort,_xlfn._xlws.FILTER(_xlfn.SWITCH(_xlpm.pri,"Critical",1,"High",2,"Medium",3,"Low",4,9),_xlpm.include), _xlpm.overdueSort,_xlfn._xlws.FILTER(--(_xlpm.dueNum<TODAY()),_xlpm.include), _xlpm.escalationSort,_xlfn._xlws.FILTER(--(_xlpm.esc="Yes"),_xlpm.include), _xlpm.riskSort,_xlfn._xlws.FILTER(_xlfn.SWITCH(_xlpm.risk,"High",1,"Medium",2,"Low",3,9),_xlpm.include), _xlfn.TAKE(_xlfn.SORTBY(_xlfn._xlws.FILTER(_xlpm.data,_xlpm.include),_xlpm.prioritySort,1,_xlpm.overdueSort,-1,_xlpm.escalationSort,-1,_xlpm.riskSort,1),5) )} -> SLT-0051 | B12: Customer Invoice Pricing Discrepancies - London Drugs | C12: Dave | D12: 46311 | E12: In Progress | F12: High | G12: High | H12: No | I12: Other | J12: 0
A13: SLT-0035 | B13: Review December salary and pay-band alignment strategy in Q4 | C13: Gene | D13: 46308 | E13: In Progress | F13: High | G13: Medium | H13: No | I13: People & Culture | J13: 0
A14: SLT-0036 | B14: RTRI Funding Application - Reapplication | C14: Dave | D14: 46307 | E14: In Progress | F14: High | G14: Medium | H14: No | I14: Cost Reduction | J14: 0
A15: SLT-0054 | B15: Vacation and Blackout Period Planning | C15: Gene | D15: 46304 | E15: In Progress | F15: High | G15: Medium | H15: No | I15: People & Culture | J15: 0
A16: SLT-0042 | B16: $700K Risk - Maple Leaf Insurance Claim Risk | C16: Dave | D16: 46321 | E16: In Progress | F16: High | G16: High | H16: Yes | I16: Other | J16: 0
A19: Recommended Review Sequence | G19: Board-Ready Controls Added
A20: 1. Review overdue, critical, high-risk and escalation items first. | G20: • Priority and risk rating
A21: 2. Review ASP Go-Live as a stand-alone executive workstream. | G21: • Strategic objective alignment
A22: 3. Review Governance & Controls as a CFO-led control register. | G22: • Financial impact classification
A23: 4. Confirm decision queue items needing CEO/CFO/SLT direction. | G23: • CEO/CFO escalation flag
A24: 5. Confirm owners, due dates, blockers and follow-up evidence. | G24: • ASP readiness stream
G25: • Decision queue and permanent register

Sheet Executive Dashboard (2)
A1: Executive Dashboard
A2: Board-ready view of open actions, overdue items, risk, escalation, ASP Go-Live, and owner accountability.
A4: Open Actions | C4: Overdue | E4: Critical Priority | G4: High Risk | I4: Escalations | K4: ASP Go-Live Items
A5: =COUNTIFS('Action Register'!$T:$T,"ACTIVE",'Action Register'!$B:$B,"<>",'Action Register'!$G:$G,"<>Completed",'Action Register'!$G:$G,"<>Cancelled") -> 29 | C5: =COUNTIFS('Action Register'!$F:$F,"<"&TODAY(),'Action Register'!$B:$B,"<>",'Action Register'!$G:$G,"<>Completed",'Action Register'!$G:$G,"<>Cancelled",'Action Register'!$G:$G,"<>Deferred") -> 10 | E5: =COUNTIFS('Action Register'!$H:$H,"Critical",'Action Register'!$B:$B,"<>") -> 0 | G5: =COUNTIFS('Action Register'!$J:$J,"High",'Action Register'!$B:$B,"<>") -> 14 | I5: =COUNTIFS('Action Register'!$L:$L,"Yes",'Action Register'!$B:$B,"<>") -> 10 | K5: =COUNTIFS('Action Register'!$K:$K,"ASP Go-Live",'Action Register'!$B:$B,"<>") -> 9
A9: Owner | B9: Open | C9: Overdue | D9: At Risk / Stuck | E9: High Risk | F9: Escalations | H9: Strategic Objective | I9: Open Items | J9: High Risk | K9: Escalations
A10: Gene | B10: =COUNTIFS('Action Register'!$D:$D,$A10,'Action Register'!$B:$B,"<>",'Action Register'!$G:$G,"<>Completed",'Action Register'!$G:$G,"<>Cancelled") -> 4 | C10: =COUNTIFS('Action Register'!$D:$D,$A10,'Action Register'!$F:$F,"<"&TODAY(),'Action Register'!$B:$B,"<>",'Action Register'!$G:$G,"<>Completed",'Action Register'!$G:$G,"<>Cancelled",'Action Register'!$G:$G,"<>Deferred") -> 4 | D10: =COUNTIFS('Action Register'!$D:$D,$A10,'Action Register'!$G:$G,"At Risk")+COUNTIFS('Action Register'!$D:$D,$A10,'Action Register'!$G:$G,"Stuck") -> 0 | E10: =COUNTIFS('Action Register'!$D:$D,$A10,'Action Register'!$J:$J,"High") -> 1 | F10: =COUNTIFS('Action Register'!$D:$D,$A10,'Action Register'!$L:$L,"Yes") -> 2 | H10: ASP Go-Live | I10: =COUNTIFS('Action Register'!$K:$K,$H10,'Action Register'!$B:$B,"<>",'Action Register'!$G:$G,"<>Completed",'Action Register'!$G:$G,"<>Cancelled") -> 5 | J10: =COUNTIFS('Action Register'!$K:$K,$H10,'Action Register'!$J:$J,"High") -> 4 | K10: =COUNTIFS('Action Register'!$K:$K,$H10,'Action Register'!$L:$L,"Yes") -> 2
A11: Dave | B11: =COUNTIFS('Action Register'!$D:$D,$A11,'Action Register'!$B:$B,"<>",'Action Register'!$G:$G,"<>Completed",'Action Register'!$G:$G,"<>Cancelled") -> 7 | C11: =COUNTIFS('Action Register'!$D:$D,$A11,'Action Register'!$F:$F,"<"&TODAY(),'Action Register'!$B:$B,"<>",'Action Register'!$G:$G,"<>Completed",'Action Register'!$G:$G,"<>Cancelled",'Action Register'!$G:$G,"<>Deferred") -> 4 | D11: =COUNTIFS('Action Register'!$D:$D,$A11,'Action Register'!$G:$G,"At Risk")+COUNTIFS('Action Register'!$D:$D,$A11,'Action Register'!$G:$G,"Stuck") -> 0 | E11: =COUNTIFS('Action Register'!$D:$D,$A11,'Action Register'!$J:$J,"High") -> 7 | F11: =COUNTIFS('Action Register'!$D:$D,$A11,'Action Register'!$L:$L,"Yes") -> 2 | H11: Governance | I11: =COUNTIFS('Action Register'!$K:$K,$H11,'Action Register'!$B:$B,"<>",'Action Register'!$G:$G,"<>Completed",'Action Register'!$G:$G,"<>Cancelled") -> 6 | J11: =COUNTIFS('Action Register'!$K:$K,$H11,'Action Register'!$J:$J,"High") -> 1 | K11: =COUNTIFS('Action Register'!$K:$K,$H11,'Action Register'!$L:$L,"Yes") -> 2
A12: Maurizio | B12: =COUNTIFS('Action Register'!$D:$D,$A12,'Action Register'!$B:$B,"<>",'Action Register'!$G:$G,"<>Completed",'Action Register'!$G:$G,"<>Cancelled") -> 1 | C12: =COUNTIFS('Action Register'!$D:$D,$A12,'Action Register'!$F:$F,"<"&TODAY(),'Action Register'!$B:$B,"<>",'Action Register'!$G:$G,"<>Completed",'Action Register'!$G:$G,"<>Cancelled",'Action Register'!$G:$G,"<>Deferred") -> 0 | D12: =COUNTIFS('Action Register'!$D:$D,$A12,'Action Register'!$G:$G,"At Risk")+COUNTIFS('Action Register'!$D:$D,$A12,'Action Register'!$G:$G,"Stuck") -> 0 | E12: =COUNTIFS('Action Register'!$D:$D,$A12,'Action Register'!$J:$J,"High") -> 1 | F12: =COUNTIFS('Action Register'!$D:$D,$A12,'Action Register'!$L:$L,"Yes") -> 2 | H12: Cost Reduction | I12: =COUNTIFS('Action Register'!$K:$K,$H12,'Action Register'!$B:$B,"<>",'Action Register'!$G:$G,"<>Completed",'Action Register'!$G:$G,"<>Cancelled") -> 2 | J12: =COUNTIFS('Action Register'!$K:$K,$H12,'Action Register'!$J:$J,"High") -> 1 | K12: =COUNTIFS('Action Register'!$K:$K,$H12,'Action Register'!$L:$L,"Yes") -> 2
A13: Tom | B13: =COUNTIFS('Action Register'!$D:$D,$A13,'Action Register'!$B:$B,"<>",'Action Register'!$G:$G,"<>Completed",'Action Register'!$G:$G,"<>Cancelled") -> 5 | C13: =COUNTIFS('Action Register'!$D:$D,$A13,'Action Register'!$F:$F,"<"&TODAY(),'Action Register'!$B:$B,"<>",'Action Register'!$G:$G,"<>Completed",'Action Register'!$G:$G,"<>Cancelled",'Action Register'!$G:$G,"<>Deferred") -> 0 | D13: =COUNTIFS('Action Register'!$D:$D,$A13,'Action Register'!$G:$G,"At Risk")+COUNTIFS('Action Register'!$D:$D,$A13,'Action Register'!$G:$G,"Stuck") -> 0 | E13: =COUNTIFS('Action Register'!$D:$D,$A13,'Action Register'!$J:$J,"High") -> 2 | F13: =COUNTIFS('Action Register'!$D:$D,$A13,'Action Register'!$L:$L,"Yes") -> 1 | H13: People & Culture | I13: =COUNTIFS('Action Register'!$K:$K,$H13,'Action Register'!$B:$B,"<>",'Action Register'!$G:$G,"<>Completed",'Action Register'!$G:$G,"<>Cancelled") -> 6 | J13: =COUNTIFS('Action Register'!$K:$K,$H13,'Action Register'!$J:$J,"High") -> 3 | K13: =COUNTIFS('Action Register'!$K:$K,$H13,'Action Register'!$L:$L,"Yes") -> 3
A14: Tony | B14: =COUNTIFS('Action Register'!$D:$D,$A14,'Action Register'!$B:$B,"<>",'Action Register'!$G:$G,"<>Completed",'Action Register'!$G:$G,"<>Cancelled") -> 1 | C14: =COUNTIFS('Action Register'!$D:$D,$A14,'Action Register'!$F:$F,"<"&TODAY(),'Action Register'!$B:$B,"<>",'Action Register'!$G:$G,"<>Completed",'Action Register'!$G:$G,"<>Cancelled",'Action Register'!$G:$G,"<>Deferred") -> 1 | D14: =COUNTIFS('Action Register'!$D:$D,$A14,'Action Register'!$G:$G,"At Risk")+COUNTIFS('Action Register'!$D:$D,$A14,'Action Register'!$G:$G,"Stuck") -> 0 | E14: =COUNTIFS('Action Register'!$D:$D,$A14,'Action Register'!$J:$J,"High") -> 0 | F14: =COUNTIFS('Action Register'!$D:$D,$A14,'Action Register'!$L:$L,"Yes") -> 0 | H14: Sierra Growth | I14: =COUNTIFS('Action Register'!$K:$K,$H14,'Action Register'!$B:$B,"<>",'Action Register'!$G:$G,"<>Completed",'Action Register'!$G:$G,"<>Cancelled") -> 0 | J14: =COUNTIFS('Action Register'!$K:$K,$H14,'Action Register'!$J:$J,"High") -> 0 | K14: =COUNTIFS('Action Register'!$K:$K,$H14,'Action Register'!$L:$L,"Yes") -> 0
A15: Sherry | B15: =COUNTIFS('Action Register'!$D:$D,$A15,'Action Register'!$B:$B,"<>",'Action Register'!$G:$G,"<>Completed",'Action Register'!$G:$G,"<>Cancelled") -> 3 | C15: =COUNTIFS('Action Register'!$D:$D,$A15,'Action Register'!$F:$F,"<"&TODAY(),'Action Register'!$B:$B,"<>",'Action Register'!$G:$G,"<>Completed",'Action Register'!$G:$G,"<>Cancelled",'Action Register'!$G:$G,"<>Deferred") -> 0 | D15: =COUNTIFS('Action Register'!$D:$D,$A15,'Action Register'!$G:$G,"At Risk")+COUNTIFS('Action Register'!$D:$D,$A15,'Action Register'!$G:$G,"Stuck") -> 0 | E15: =COUNTIFS('Action Register'!$D:$D,$A15,'Action Register'!$J:$J,"High") -> 0 | F15: =COUNTIFS('Action Register'!$D:$D,$A15,'Action Register'!$L:$L,"Yes") -> 1 | H15: Federal Licence | I15: =COUNTIFS('Action Register'!$K:$K,$H15,'Action Register'!$B:$B,"<>",'Action Register'!$G:$G,"<>Completed",'Action Register'!$G:$G,"<>Cancelled") -> 0 | J15: =COUNTIFS('Action Register'!$K:$K,$H15,'Action Register'!$J:$J,"High") -> 0 | K15: =COUNTIFS('Action Register'!$K:$K,$H15,'Action Register'!$L:$L,"Yes") -> 0
A16: Sandy | B16: =COUNTIFS('Action Register'!$D:$D,$A16,'Action Register'!$B:$B,"<>",'Action Register'!$G:$G,"<>Completed",'Action Register'!$G:$G,"<>Cancelled") -> 0 | C16: =COUNTIFS('Action Register'!$D:$D,$A16,'Action Register'!$F:$F,"<"&TODAY(),'Action Register'!$B:$B,"<>",'Action Register'!$G:$G,"<>Completed",'Action Register'!$G:$G,"<>Cancelled",'Action Register'!$G:$G,"<>Deferred") -> 0 | D16: =COUNTIFS('Action Register'!$D:$D,$A16,'Action Register'!$G:$G,"At Risk")+COUNTIFS('Action Register'!$D:$D,$A16,'Action Register'!$G:$G,"Stuck") -> 0 | E16: =COUNTIFS('Action Register'!$D:$D,$A16,'Action Register'!$J:$J,"High") -> 0 | F16: =COUNTIFS('Action Register'!$D:$D,$A16,'Action Register'!$L:$L,"Yes") -> 1 | H16: Food Safety | I16: =COUNTIFS('Action Register'!$K:$K,$H16,'Action Register'!$B:$B,"<>",'Action Register'!$G:$G,"<>Completed",'Action Register'!$G:$G,"<>Cancelled") -> 1 | J16: =COUNTIFS('Action Register'!$K:$K,$H16,'Action Register'!$J:$J,"High") -> 0 | K16: =COUNTIFS('Action Register'!$K:$K,$H16,'Action Register'!$L:$L,"Yes") -> 0
A17: Other | B17: =COUNTIFS('Action Register'!$D:$D,$A17,'Action Register'!$B:$B,"<>",'Action Register'!$G:$G,"<>Completed",'Action Register'!$G:$G,"<>Cancelled") -> 0 | C17: =COUNTIFS('Action Register'!$D:$D,$A17,'Action Register'!$F:$F,"<"&TODAY(),'Action Register'!$B:$B,"<>",'Action Register'!$G:$G,"<>Completed",'Action Register'!$G:$G,"<>Cancelled",'Action Register'!$G:$G,"<>Deferred") -> 0 | D17: =COUNTIFS('Action Register'!$D:$D,$A17,'Action Register'!$G:$G,"At Risk")+COUNTIFS('Action Register'!$D:$D,$A17,'Action Register'!$G:$G,"Stuck") -> 0 | E17: =COUNTIFS('Action Register'!$D:$D,$A17,'Action Register'!$J:$J,"High") -> 0 | F17: =COUNTIFS('Action Register'!$D:$D,$A17,'Action Register'!$L:$L,"Yes") -> 0 | H17: Commercial Growth | I17: =COUNTIFS('Action Register'!$K:$K,$H17,'Action Register'!$B:$B,"<>",'Action Register'!$G:$G,"<>Completed",'Action Register'!$G:$G,"<>Cancelled") -> 3 | J17: =COUNTIFS('Action Register'!$K:$K,$H17,'Action Register'!$J:$J,"High") -> 1 | K17: =COUNTIFS('Action Register'!$K:$K,$H17,'Action Register'!$L:$L,"Yes") -> 0
A18: Executive Summary Charts
A37: Recommended Weekly SLT Review Sequence
A38: 1. Review Critical / High Risk / Escalation items first.
A39: 2. Review ASP Go-Live and Governance & Controls as separate executive categories.
A40: 3. Confirm overdue decisions and items requiring CEO/CFO attention.
A41: 4. Review owner accountability dashboard for bottlenecks.
A42: 5. Move decisions from Decision Queue to Decision Log once made, with follow-up owner and due date.

Sheet Board Summary
A1: SLT Action Tracker - Board Summary
A2: Prepared for executive review. Focus areas: overdue decisions, critical/high-risk items, escalation points, ASP Go-Live readiness, and governance controls.
A4: Prepared for | B4: SLT / Board Review | D4: Prepared by | G4: Version | J4: Date | K4: 46219
A6: Open Actions | B6: Overdue | C6: Critical Priority | E6: High Priority | G6: High Risk | I6: Escalations | J6: ASP Go-Live Items
A7: ='Executive Dashboard'!A5 -> 29 | B7: ='Executive Dashboard'!C5 -> 10 | C7: ='Executive Dashboard'!F5 -> 0 | E7: ='Executive Dashboard'!I5 -> 8 | G7: ='Executive Dashboard'!K5 -> 6 | I7: ='Executive Dashboard'!M5 -> 3 | J7: ='Executive Dashboard'!O5 -> 5
A10: Items Requiring Executive Attention
A11: ID | B11: Item | C11: Owner | D11: Due Date | E11: Status | F11: Priority | G11: Risk | H11: Escalation | I11: Strategic Objective | J11: Board Note
A12: {=_xlfn.LET( _xlpm.ids,'Action Register'!$A$5:$A$104, _xlpm.items,'Action Register'!$B$5:$B$104, _xlpm.owners,'Action Register'!$D$5:$D$104, _xlpm.due,'Action Register'!$F$5:$F$104, _xlpm.dueNum,IFERROR(--_xlpm.due,DATEVALUE(_xlpm.due)), _xlpm.status,'Action Register'!$G$5:$G$104, _xlpm.pri,'Action Register'!$H$5:$H$104, _xlpm.risk,'Action Register'!$J$5:$J$104, _xlpm.obj,'Action Register'!$K$5:$K$104, _xlpm.esc,'Action Register'!$L$5:$L$104, _xlpm.note,'Action Register'!$P$5:$P$104, _xlpm.active,'Action Register'!$T$5:$T$104, _xlpm.include,(_xlpm.items<>"")*(_xlpm.active="ACTIVE")*((_xlpm.pri="Critical")+(_xlpm.pri="High")+(_xlpm.risk="High")+(_xlpm.esc="Yes")+(_xlpm.due<=TODAY())), _xlpm.data,CHOOSE({1,2,3,4,5,6,7,8,9,10},_xlpm.ids,_xlpm.items,IF(_xlpm.owners="","",_xlpm.owners),_xlpm.due,_xlpm.status,_xlpm.pri,_xlpm.risk,_xlpm.esc,_xlpm.obj,IF(_xlpm.note="","",_xlpm.note)), _xlpm.prioritySort,_xlfn._xlws.FILTER(_xlfn.SWITCH(_xlpm.pri,"Critical",1,"High",2,"Medium",3,"Low",4,9),_xlpm.include), _xlpm.overdueSort,_xlfn._xlws.FILTER(--(_xlpm.dueNum<TODAY()),_xlpm.include), _xlpm.escalationSort,_xlfn._xlws.FILTER(--(_xlpm.esc="Yes"),_xlpm.include), _xlpm.riskSort,_xlfn._xlws.FILTER(_xlfn.SWITCH(_xlpm.risk,"High",1,"Medium",2,"Low",3,9),_xlpm.include), _xlfn.SORTBY(_xlfn._xlws.FILTER(_xlpm.data,_xlpm.include),_xlpm.prioritySort,1,_xlpm.overdueSort,-1,_xlpm.escalationSort,-1,_xlpm.riskSort,1) )} -> SLT-0051 | B12: Customer Invoice Pricing Discrepancies - London Drugs | C12: Dave | D12: 46311 | E12: In Progress | F12: High | G12: High | H12: No | I12: Other
A13: SLT-0035 | B13: Review December salary and pay-band alignment strategy in Q4 | C13: Gene | D13: 46308 | E13: In Progress | F13: High | G13: Medium | H13: No | I13: People & Culture
A14: SLT-0036 | B14: RTRI Funding Application - Reapplication | C14: Dave | D14: 46307 | E14: In Progress | F14: High | G14: Medium | H14: No | I14: Cost Reduction
A15: SLT-0054 | B15: Vacation and Blackout Period Planning | C15: Gene | D15: 46304 | E15: In Progress | F15: High | G15: Medium | H15: No | I15: People & Culture
A16: SLT-0042 | B16: $700K Risk - Maple Leaf Insurance Claim Risk | C16: Dave | D16: 46321 | E16: In Progress | F16: High | G16: High | H16: Yes | I16: Other
A17: SLT-0015 | B17: YVF Yield Report | C17: Tom | D17: 46322 | E17: In Progress | F17: High | G17: High | H17: No | I17: Commercial Growth | J17: Original request - 1. Confirm yield reports are being distributed to YVF stakeholders (Ryan and James). 2. Add the dollar impact of yields to YVF reports. Will support 2027 transfer price piece
A18: SLT-0025 | B18: Chilled Water System Change Order (OCO-008) | C18: Colin | D18: 46321 | E18: Assigned | F18: High | G18: High | H18: No | I18: ASP Go-Live | J18: Leadership also maintained that responsibility for the omission rests with Coldbox and should not be transferred to its subcontractor.
A19: SLT-0043 | B19: $200K - Inventory issue from 2025 year-end | C19: Dave | D19: 46321 | E19: In Progress | F19: High | G19: High | H19: No | I19: Other | J19: Resolve and record the $200K inventory variance from FY2025 year-end
A20: SLT-0001 | B20: Employee Payroll Advances | C20: Gene | D20: 46254 | E20: In Progress | F20: Medium | G20: Medium | H20: No | I20: Governance | J20: Governance fields added for SLT visibility.
A21: SLT-0008 | B21: Develop a Performance Plan for Tatiana | C21: Adam | D21: 46314 | E21: In Progress | F21: Medium | G21: Medium | H21: No | I21: People & Culture
A22: SLT-0012 | B22: PO Policy Rollout | C22: Dave | D22: 46316 | E22: In Progress | F22: Medium | G22: Medium | H22: No | I22: Governance | J22: Brought from deferred decision on May 11, 2026. Evaluated 2 vendor proposals. Sherry Crawford and Practical Approach.
A23: SLT-0029 | B23: Workorder Closure - Sierra | C23: Dave | D23: 46310 | E23: In Progress | F23: Medium | G23: Medium | H23: No | I23: Governance
A24: SLT-0017 | B24: Deloitte's Best Managed Companies | C24: Tony | D24: 46311 | E24: In Progress | F24: Medium | G24: Low | H24: No | I24: Other
A25: SLT-0004 | B25: CFO Governance & Controls Register | C25: Sherry | D25: 46321 | E25: In Progress | F25: Medium | G25: Medium | H25: Yes | I25: Governance | J25: CFO governance visibility for policies, internal audit, grants, legal review, and controls.
A26: SLT-0044 | B26: DSI Machine (Camera) Root Cause Analysis ($80K value equipment) | C26: Adam | D26: 46321 | E26: In Progress | F26: Medium | G26: Medium | H26: Yes | I26: Cost Reduction
A27: SLT-0022 | B27: Division 9 Steel - Change Order | C27: Colin | D27: 46321 | E27: In Progress | F27: Medium | G27: High | H27: No | I27: ASP Go-Live | J27: Per Colin's Decision Brief submission $410,559.82 remains available for interior alterations according to CBB. What happened to the $800K? Recall this monthly to SLT meetings until it is resolved.
A28: SLT-0048 | B28: Sierra Reserved Parking Policy | C28: Gene | D28: 46310 | E28: In Progress | F28: Low | G28: Low | H28: No | I28: People & Culture
A129: Recommended Review Sequence | G129: Board-Ready Controls Added
A130: 1. Review overdue, critical, high-risk and escalation items first. | G130: • Priority and risk rating
A131: 2. Review ASP Go-Live as a stand-alone executive workstream. | G131: • Strategic objective alignment
A132: 3. Review Governance & Controls as a CFO-led control register. | G132: • Financial impact classification
A133: 4. Confirm decision queue items needing CEO/CFO/SLT direction. | G133: • CEO/CFO escalation flag
A134: 5. Confirm owners, due dates, blockers and follow-up evidence. | G134: • ASP readiness stream
G135: • Decision queue and permanent register

Sheet Executive Dashboard
A1: Executive Dashboard
A2: Board-ready view of open actions, overdue items, risk, escalation, ASP Go-Live, and owner accountability.
A4: Open Actions | C4: Over Due | F4: Critical Priority | I4: High Priority | K4: High Risk | M4: Escalations | O4: ASP Go-Live Items
A5: =COUNTIFS('Action Register'!$T:$T,"ACTIVE",'Action Register'!$B:$B,"<>") -> 29 | C5: =COUNTIFS('Action Register'!$T:$T,"ACTIVE",'Action Register'!$F:$F,"<>",'Action Register'!$F:$F,"<"&TODAY(),'Action Register'!$B:$B,"<>") -> 10 | F5: =COUNTIFS('Action Register'!$T:$T,"ACTIVE",'Action Register'!$H:$H,"Critical",'Action Register'!$B:$B,"<>") -> 0 | I5: =COUNTIFS('Action Register'!$T:$T,"ACTIVE",'Action Register'!$H:$H,"High",'Action Register'!$B:$B,"<>") -> 8 | K5: =COUNTIFS('Action Register'!$T:$T,"ACTIVE",'Action Register'!$J:$J,"High",'Action Register'!$B:$B,"<>") -> 6 | M5: =COUNTIFS('Action Register'!$T:$T,"ACTIVE",'Action Register'!$L:$L,"Yes",'Action Register'!$B:$B,"<>") -> 3 | O5: =COUNTIFS('Action Register'!$T:$T,"ACTIVE",'Action Register'!$K:$K,"ASP Go-Live",'Action Register'!$B:$B,"<>") -> 5
A9: Owner | B9: Open | C9: Overdue | D9: Critical Priority | E9: High Priority | F9: High Risk | G9: At Risk / Stuck | H9: Escalations | J9: Strategic Objective | K9: Open Items | L9: Overdue | M9: Critical priority | N9: high priority | O9: High Risk | P9: Escalations
A10: Gene | B10: =COUNTIFS('Action Register'!$D:$D,$A10,'Action Register'!$B:$B,"<>",'Action Register'!$G:$G,"<>Completed",'Action Register'!$G:$G,"<>Cancelled") -> 4 | C10: =COUNTIFS('Action Register'!$D:$D,$A10,'Action Register'!$F:$F,"<"&TODAY(),'Action Register'!$B:$B,"<>",'Action Register'!$G:$G,"<>Closed",'Action Register'!$G:$G,"<>Completed",'Action Register'!$G:$G,"<>Cancelled",'Action Register'!$G:$G,"<>Deferred") -> 4 | D10: =COUNTIFS('Action Register'!$D:$D,$A10,'Action Register'!$H:$H,"Critical",'Action Register'!$G:$G,"<>Closed",'Action Register'!$G:$G,"<>Completed",'Action Register'!$G:$G,"<>Cancelled",'Action Register'!$G:$G,"<>Deferred") -> 0 | E10: =COUNTIFS('Action Register'!$D:$D,$A10,'Action Register'!$H:$H,"High",'Action Register'!$G:$G,"<>Closed",'Action Register'!$G:$G,"<>Completed",'Action Register'!$G:$G,"<>Cancelled",'Action Register'!$G:$G,"<>Deferred") -> 2 | F10: =COUNTIFS('Action Register'!$D:$D,$A10,'Action Register'!$J:$J,"High",'Action Register'!$G:$G,"<>Closed",'Action Register'!$G:$G,"<>Completed",'Action Register'!$G:$G,"<>Cancelled",'Action Register'!$G:$G,"<>Deferred") -> 0 | G10: =COUNTIFS('Action Register'!$D:$D,$A10,'Action Register'!$G:$G,"At Risk")+COUNTIFS('Action Register'!$D:$D,$A10,'Action Register'!$G:$G,"Stuck") -> 0 | H10: =COUNTIFS('Action Register'!$D:$D,$A10,'Action Register'!$L:$L,"Yes",'Action Register'!$G:$G,"<>Closed",'Action Register'!$G:$G,"<>Completed",'Action Register'!$G:$G,"<>Cancelled",'Action Register'!$G:$G,"<>Deferred") -> 0 | J10: ASP Go-Live | K10: =COUNTIFS('Action Register'!$K:$K,$J10,'Action Register'!$B:$B,"<>",'Action Register'!$G:$G,"<>Closed",'Action Register'!$G:$G,"<>Completed",'Action Register'!$G:$G,"<>Cancelled",'Action Register'!$G:$G,"<>Deferred") -> 5 | L10: =COUNTIFS('Action Register'!$K:$K,$J10,'Action Register'!$F:$F,"<"&TODAY(),'Action Register'!$B:$B,"<>",'Action Register'!$G:$G,"<>Closed",'Action Register'!$G:$G,"<>Completed",'Action Register'!$G:$G,"<>Cancelled",'Action Register'!$G:$G,"<>Deferred") -> 0 | M10: =COUNTIFS('Action Register'!$K:$K,$J10,'Action Register'!$H:$H,"Critical",'Action Register'!$G:$G,"<>Closed",'Action Register'!$G:$G,"<>Completed",'Action Register'!$G:$G,"<>Cancelled",'Action Register'!$G:$G,"<>Deferred") -> 0 | N10: =COUNTIFS('Action Register'!$K:$K,$J10,'Action Register'!$H:$H,"High",'Action Register'!$G:$G,"<>Closed",'Action Register'!$G:$G,"<>Completed",'Action Register'!$G:$G,"<>Cancelled",'Action Register'!$G:$G,"<>Deferred") -> 1 | O10: =COUNTIFS('Action Register'!$K:$K,$J10,'Action Register'!$J:$J,"High",'Action Register'!$G:$G,"<>Closed",'Action Register'!$G:$G,"<>Completed",'Action Register'!$G:$G,"<>Cancelled",'Action Register'!$G:$G,"<>Deferred") -> 2 | P10: =COUNTIFS('Action Register'!$K:$K,$J10,'Action Register'!$L:$L,"Yes",'Action Register'!$G:$G,"<>Closed",'Action Register'!$G:$G,"<>Completed",'Action Register'!$G:$G,"<>Cancelled",'Action Register'!$G:$G,"<>Deferred") -> 0
A11: Dave | B11: =COUNTIFS('Action Register'!$D:$D,$A11,'Action Register'!$B:$B,"<>",'Action Register'!$G:$G,"<>Completed",'Action Register'!$G:$G,"<>Cancelled") -> 7 | C11: =COUNTIFS('Action Register'!$D:$D,$A11,'Action Register'!$F:$F,"<"&TODAY(),'Action Register'!$B:$B,"<>",'Action Register'!$G:$G,"<>Closed",'Action Register'!$G:$G,"<>Completed",'Action Register'!$G:$G,"<>Cancelled",'Action Register'!$G:$G,"<>Deferred") -> 4 | D11: =COUNTIFS('Action Register'!$D:$D,$A11,'Action Register'!$H:$H,"Critical",'Action Register'!$G:$G,"<>Closed",'Action Register'!$G:$G,"<>Completed",'Action Register'!$G:$G,"<>Cancelled",'Action Register'!$G:$G,"<>Deferred") -> 0 | E11: =COUNTIFS('Action Register'!$D:$D,$A11,'Action Register'!$H:$H,"High",'Action Register'!$G:$G,"<>Closed",'Action Register'!$G:$G,"<>Completed",'Action Register'!$G:$G,"<>Cancelled",'Action Register'!$G:$G,"<>Deferred") -> 4 | F11: =COUNTIFS('Action Register'!$D:$D,$A11,'Action Register'!$J:$J,"High",'Action Register'!$G:$G,"<>Closed",'Action Register'!$G:$G,"<>Completed",'Action Register'!$G:$G,"<>Cancelled",'Action Register'!$G:$G,"<>Deferred") -> 3 | G11: =COUNTIFS('Action Register'!$D:$D,$A11,'Action Register'!$G:$G,"At Risk")+COUNTIFS('Action Register'!$D:$D,$A11,'Action Register'!$G:$G,"Stuck") -> 0 | H11: =COUNTIFS('Action Register'!$D:$D,$A11,'Action Register'!$L:$L,"Yes",'Action Register'!$G:$G,"<>Closed",'Action Register'!$G:$G,"<>Completed",'Action Register'!$G:$G,"<>Cancelled",'Action Register'!$G:$G,"<>Deferred") -> 1 | J11: Governance | K11: =COUNTIFS('Action Register'!$K:$K,$J11,'Action Register'!$B:$B,"<>",'Action Register'!$G:$G,"<>Closed",'Action Register'!$G:$G,"<>Completed",'Action Register'!$G:$G,"<>Cancelled",'Action Register'!$G:$G,"<>Deferred") -> 6 | L11: =COUNTIFS('Action Register'!$K:$K,$J11,'Action Register'!$F:$F,"<"&TODAY(),'Action Register'!$B:$B,"<>",'Action Register'!$G:$G,"<>Closed",'Action Register'!$G:$G,"<>Completed",'Action Register'!$G:$G,"<>Cancelled",'Action Register'!$G:$G,"<>Deferred") -> 3 | M11: =COUNTIFS('Action Register'!$K:$K,$J11,'Action Register'!$H:$H,"Critical",'Action Register'!$G:$G,"<>Closed",'Action Register'!$G:$G,"<>Completed",'Action Register'!$G:$G,"<>Cancelled",'Action Register'!$G:$G,"<>Deferred") -> 0 | N11: =COUNTIFS('Action Register'!$K:$K,$J11,'Action Register'!$H:$H,"High",'Action Register'!$G:$G,"<>Closed",'Action Register'!$G:$G,"<>Completed",'Action Register'!$G:$G,"<>Cancelled",'Action Register'!$G:$G,"<>Deferred") -> 0 | O11: =COUNTIFS('Action Register'!$K:$K,$J11,'Action Register'!$J:$J,"High",'Action Register'!$G:$G,"<>Closed",'Action Register'!$G:$G,"<>Completed",'Action Register'!$G:$G,"<>Cancelled",'Action Register'!$G:$G,"<>Deferred") -> 0 | P11: =COUNTIFS('Action Register'!$K:$K,$J11,'Action Register'!$L:$L,"Yes",'Action Register'!$G:$G,"<>Closed",'Action Register'!$G:$G,"<>Completed",'Action Register'!$G:$G,"<>Cancelled",'Action Register'!$G:$G,"<>Deferred") -> 1
A12: Maurizio | B12: =COUNTIFS('Action Register'!$D:$D,$A12,'Action Register'!$B:$B,"<>",'Action Register'!$G:$G,"<>Completed",'Action Register'!$G:$G,"<>Cancelled") -> 1 | C12: =COUNTIFS('Action Register'!$D:$D,$A12,'Action Register'!$F:$F,"<"&TODAY(),'Action Register'!$B:$B,"<>",'Action Register'!$G:$G,"<>Closed",'Action Register'!$G:$G,"<>Completed",'Action Register'!$G:$G,"<>Cancelled",'Action Register'!$G:$G,"<>Deferred") -> 0 | D12: =COUNTIFS('Action Register'!$D:$D,$A12,'Action Register'!$H:$H,"Critical",'Action Register'!$G:$G,"<>Closed",'Action Register'!$G:$G,"<>Completed",'Action Register'!$G:$G,"<>Cancelled",'Action Register'!$G:$G,"<>Deferred") -> 0 | E12: =COUNTIFS('Action Register'!$D:$D,$A12,'Action Register'!$H:$H,"High",'Action Register'!$G:$G,"<>Closed",'Action Register'!$G:$G,"<>Completed",'Action Register'!$G:$G,"<>Cancelled",'Action Register'!$G:$G,"<>Deferred") -> 0 | F12: =COUNTIFS('Action Register'!$D:$D,$A12,'Action Register'!$J:$J,"High",'Action Register'!$G:$G,"<>Closed",'Action Register'!$G:$G,"<>Completed",'Action Register'!$G:$G,"<>Cancelled",'Action Register'!$G:$G,"<>Deferred") -> 0 | G12: =COUNTIFS('Action Register'!$D:$D,$A12,'Action Register'!$G:$G,"At Risk")+COUNTIFS('Action Register'!$D:$D,$A12,'Action Register'!$G:$G,"Stuck") -> 0 | H12: =COUNTIFS('Action Register'!$D:$D,$A12,'Action Register'!$L:$L,"Yes",'Action Register'!$G:$G,"<>Closed",'Action Register'!$G:$G,"<>Completed",'Action Register'!$G:$G,"<>Cancelled",'Action Register'!$G:$G,"<>Deferred") -> 0 | J12: Cost Reduction | K12: =COUNTIFS('Action Register'!$K:$K,$J12,'Action Register'!$B:$B,"<>",'Action Register'!$G:$G,"<>Closed",'Action Register'!$G:$G,"<>Completed",'Action Register'!$G:$G,"<>Cancelled",'Action Register'!$G:$G,"<>Deferred") -> 2 | L12: =COUNTIFS('Action Register'!$K:$K,$J12,'Action Register'!$F:$F,"<"&TODAY(),'Action Register'!$B:$B,"<>",'Action Register'!$G:$G,"<>Closed",'Action Register'!$G:$G,"<>Completed",'Action Register'!$G:$G,"<>Cancelled",'Action Register'!$G:$G,"<>Deferred") -> 1 | M12: =COUNTIFS('Action Register'!$K:$K,$J12,'Action Register'!$H:$H,"Critical",'Action Register'!$G:$G,"<>Closed",'Action Register'!$G:$G,"<>Completed",'Action Register'!$G:$G,"<>Cancelled",'Action Register'!$G:$G,"<>Deferred") -> 0 | N12: =COUNTIFS('Action Register'!$K:$K,$J12,'Action Register'!$H:$H,"High",'Action Register'!$G:$G,"<>Closed",'Action Register'!$G:$G,"<>Completed",'Action Register'!$G:$G,"<>Cancelled",'Action Register'!$G:$G,"<>Deferred") -> 1 | O12: =COUNTIFS('Action Register'!$K:$K,$J12,'Action Register'!$J:$J,"High",'Action Register'!$G:$G,"<>Closed",'Action Register'!$G:$G,"<>Completed",'Action Register'!$G:$G,"<>Cancelled",'Action Register'!$G:$G,"<>Deferred") -> 0 | P12: =COUNTIFS('Action Register'!$K:$K,$J12,'Action Register'!$L:$L,"Yes",'Action Register'!$G:$G,"<>Closed",'Action Register'!$G:$G,"<>Completed",'Action Register'!$G:$G,"<>Cancelled",'Action Register'!$G:$G,"<>Deferred") -> 1
A13: Tom | B13: =COUNTIFS('Action Register'!$D:$D,$A13,'Action Register'!$B:$B,"<>",'Action Register'!$G:$G,"<>Completed",'Action Register'!$G:$G,"<>Cancelled") -> 5 | C13: =COUNTIFS('Action Register'!$D:$D,$A13,'Action Register'!$F:$F,"<"&TODAY(),'Action Register'!$B:$B,"<>",'Action Register'!$G:$G,"<>Closed",'Action Register'!$G:$G,"<>Completed",'Action Register'!$G:$G,"<>Cancelled",'Action Register'!$G:$G,"<>Deferred") -> 0 | D13: =COUNTIFS('Action Register'!$D:$D,$A13,'Action Register'!$H:$H,"Critical",'Action Register'!$G:$G,"<>Closed",'Action Register'!$G:$G,"<>Completed",'Action Register'!$G:$G,"<>Cancelled",'Action Register'!$G:$G,"<>Deferred") -> 0 | E13: =COUNTIFS('Action Register'!$D:$D,$A13,'Action Register'!$H:$H,"High",'Action Register'!$G:$G,"<>Closed",'Action Register'!$G:$G,"<>Completed",'Action Register'!$G:$G,"<>Cancelled",'Action Register'!$G:$G,"<>Deferred") -> 1 | F13: =COUNTIFS('Action Register'!$D:$D,$A13,'Action Register'!$J:$J,"High",'Action Register'!$G:$G,"<>Closed",'Action Register'!$G:$G,"<>Completed",'Action Register'!$G:$G,"<>Cancelled",'Action Register'!$G:$G,"<>Deferred") -> 1 | G13: =COUNTIFS('Action Register'!$D:$D,$A13,'Action Register'!$G:$G,"At Risk")+COUNTIFS('Action Register'!$D:$D,$A13,'Action Register'!$G:$G,"Stuck") -> 0 | H13: =COUNTIFS('Action Register'!$D:$D,$A13,'Action Register'!$L:$L,"Yes",'Action Register'!$G:$G,"<>Closed",'Action Register'!$G:$G,"<>Completed",'Action Register'!$G:$G,"<>Cancelled",'Action Register'!$G:$G,"<>Deferred") -> 0 | J13: People & Culture | K13: =COUNTIFS('Action Register'!$K:$K,$J13,'Action Register'!$B:$B,"<>",'Action Register'!$G:$G,"<>Closed",'Action Register'!$G:$G,"<>Completed",'Action Register'!$G:$G,"<>Cancelled",'Action Register'!$G:$G,"<>Deferred") -> 6 | L13: =COUNTIFS('Action Register'!$K:$K,$J13,'Action Register'!$F:$F,"<"&TODAY(),'Action Register'!$B:$B,"<>",'Action Register'!$G:$G,"<>Closed",'Action Register'!$G:$G,"<>Completed",'Action Register'!$G:$G,"<>Cancelled",'Action Register'!$G:$G,"<>Deferred") -> 4 | M13: =COUNTIFS('Action Register'!$K:$K,$J13,'Action Register'!$H:$H,"Critical",'Action Register'!$G:$G,"<>Closed",'Action Register'!$G:$G,"<>Completed",'Action Register'!$G:$G,"<>Cancelled",'Action Register'!$G:$G,"<>Deferred") -> 0 | N13: =COUNTIFS('Action Register'!$K:$K,$J13,'Action Register'!$H:$H,"High",'Action Register'!$G:$G,"<>Closed",'Action Register'!$G:$G,"<>Completed",'Action Register'!$G:$G,"<>Cancelled",'Action Register'!$G:$G,"<>Deferred") -> 2 | O13: =COUNTIFS('Action Register'!$K:$K,$J13,'Action Register'!$J:$J,"High",'Action Register'!$G:$G,"<>Closed",'Action Register'!$G:$G,"<>Completed",'Action Register'!$G:$G,"<>Cancelled",'Action Register'!$G:$G,"<>Deferred") -> 0 | P13: =COUNTIFS('Action Register'!$K:$K,$J13,'Action Register'!$L:$L,"Yes",'Action Register'!$G:$G,"<>Closed",'Action Register'!$G:$G,"<>Completed",'Action Register'!$G:$G,"<>Cancelled",'Action Register'!$G:$G,"<>Deferred") -> 0
A14: Tony | B14: =COUNTIFS('Action Register'!$D:$D,$A14,'Action Register'!$B:$B,"<>",'Action Register'!$G:$G,"<>Completed",'Action Register'!$G:$G,"<>Cancelled") -> 1 | C14: =COUNTIFS('Action Register'!$D:$D,$A14,'Action Register'!$F:$F,"<"&TODAY(),'Action Register'!$B:$B,"<>",'Action Register'!$G:$G,"<>Closed",'Action Register'!$G:$G,"<>Completed",'Action Register'!$G:$G,"<>Cancelled",'Action Register'!$G:$G,"<>Deferred") -> 1 | D14: =COUNTIFS('Action Register'!$D:$D,$A14,'Action Register'!$H:$H,"Critical",'Action Register'!$G:$G,"<>Closed",'Action Register'!$G:$G,"<>Completed",'Action Register'!$G:$G,"<>Cancelled",'Action Register'!$G:$G,"<>Deferred") -> 0 | E14: =COUNTIFS('Action Register'!$D:$D,$A14,'Action Register'!$H:$H,"High",'Action Register'!$G:$G,"<>Closed",'Action Register'!$G:$G,"<>Completed",'Action Register'!$G:$G,"<>Cancelled",'Action Register'!$G:$G,"<>Deferred") -> 0 | F14: =COUNTIFS('Action Register'!$D:$D,$A14,'Action Register'!$J:$J,"High",'Action Register'!$G:$G,"<>Closed",'Action Register'!$G:$G,"<>Completed",'Action Register'!$G:$G,"<>Cancelled",'Action Register'!$G:$G,"<>Deferred") -> 0 | G14: =COUNTIFS('Action Register'!$D:$D,$A14,'Action Register'!$G:$G,"At Risk")+COUNTIFS('Action Register'!$D:$D,$A14,'Action Register'!$G:$G,"Stuck") -> 0 | H14: =COUNTIFS('Action Register'!$D:$D,$A14,'Action Register'!$L:$L,"Yes",'Action Register'!$G:$G,"<>Closed",'Action Register'!$G:$G,"<>Completed",'Action Register'!$G:$G,"<>Cancelled",'Action Register'!$G:$G,"<>Deferred") -> 0 | J14: Sierra Growth | K14: =COUNTIFS('Action Register'!$K:$K,$J14,'Action Register'!$B:$B,"<>",'Action Register'!$G:$G,"<>Closed",'Action Register'!$G:$G,"<>Completed",'Action Register'!$G:$G,"<>Cancelled",'Action Register'!$G:$G,"<>Deferred") -> 0 | L14: =COUNTIFS('Action Register'!$K:$K,$J14,'Action Register'!$F:$F,"<"&TODAY(),'Action Register'!$B:$B,"<>",'Action Register'!$G:$G,"<>Closed",'Action Register'!$G:$G,"<>Completed",'Action Register'!$G:$G,"<>Cancelled",'Action Register'!$G:$G,"<>Deferred") -> 0 | M14: =COUNTIFS('Action Register'!$K:$K,$J14,'Action Register'!$H:$H,"Critical",'Action Register'!$G:$G,"<>Closed",'Action Register'!$G:$G,"<>Completed",'Action Register'!$G:$G,"<>Cancelled",'Action Register'!$G:$G,"<>Deferred") -> 0 | N14: =COUNTIFS('Action Register'!$K:$K,$J14,'Action Register'!$H:$H,"High",'Action Register'!$G:$G,"<>Closed",'Action Register'!$G:$G,"<>Completed",'Action Register'!$G:$G,"<>Cancelled",'Action Register'!$G:$G,"<>Deferred") -> 0 | O14: =COUNTIFS('Action Register'!$K:$K,$J14,'Action Register'!$J:$J,"High",'Action Register'!$G:$G,"<>Closed",'Action Register'!$G:$G,"<>Completed",'Action Register'!$G:$G,"<>Cancelled",'Action Register'!$G:$G,"<>Deferred") -> 0 | P14: =COUNTIFS('Action Register'!$K:$K,$J14,'Action Register'!$L:$L,"Yes",'Action Register'!$G:$G,"<>Closed",'Action Register'!$G:$G,"<>Completed",'Action Register'!$G:$G,"<>Cancelled",'Action Register'!$G:$G,"<>Deferred") -> 0
A15: Sherry | B15: =COUNTIFS('Action Register'!$D:$D,$A15,'Action Register'!$B:$B,"<>",'Action Register'!$G:$G,"<>Completed",'Action Register'!$G:$G,"<>Cancelled") -> 3 | C15: =COUNTIFS('Action Register'!$D:$D,$A15,'Action Register'!$F:$F,"<"&TODAY(),'Action Register'!$B:$B,"<>",'Action Register'!$G:$G,"<>Closed",'Action Register'!$G:$G,"<>Completed",'Action Register'!$G:$G,"<>Cancelled",'Action Register'!$G:$G,"<>Deferred") -> 0 | D15: =COUNTIFS('Action Register'!$D:$D,$A15,'Action Register'!$H:$H,"Critical",'Action Register'!$G:$G,"<>Closed",'Action Register'!$G:$G,"<>Completed",'Action Register'!$G:$G,"<>Cancelled",'Action Register'!$G:$G,"<>Deferred") -> 0 | E15: =COUNTIFS('Action Register'!$D:$D,$A15,'Action Register'!$H:$H,"High",'Action Register'!$G:$G,"<>Closed",'Action Register'!$G:$G,"<>Completed",'Action Register'!$G:$G,"<>Cancelled",'Action Register'!$G:$G,"<>Deferred") -> 0 | F15: =COUNTIFS('Action Register'!$D:$D,$A15,'Action Register'!$J:$J,"High",'Action Register'!$G:$G,"<>Closed",'Action Register'!$G:$G,"<>Completed",'Action Register'!$G:$G,"<>Cancelled",'Action Register'!$G:$G,"<>Deferred") -> 0 | G15: =COUNTIFS('Action Register'!$D:$D,$A15,'Action Register'!$G:$G,"At Risk")+COUNTIFS('Action Register'!$D:$D,$A15,'Action Register'!$G:$G,"Stuck") -> 0 | H15: =COUNTIFS('Action Register'!$D:$D,$A15,'Action Register'!$L:$L,"Yes",'Action Register'!$G:$G,"<>Closed",'Action Register'!$G:$G,"<>Completed",'Action Register'!$G:$G,"<>Cancelled",'Action Register'!$G:$G,"<>Deferred") -> 1 | J15: Federal Licence | K15: =COUNTIFS('Action Register'!$K:$K,$J15,'Action Register'!$B:$B,"<>",'Action Register'!$G:$G,"<>Closed",'Action Register'!$G:$G,"<>Completed",'Action Register'!$G:$G,"<>Cancelled",'Action Register'!$G:$G,"<>Deferred") -> 0 | L15: =COUNTIFS('Action Register'!$K:$K,$J15,'Action Register'!$F:$F,"<"&TODAY(),'Action Register'!$B:$B,"<>",'Action Register'!$G:$G,"<>Closed",'Action Register'!$G:$G,"<>Completed",'Action Register'!$G:$G,"<>Cancelled",'Action Register'!$G:$G,"<>Deferred") -> 0 | M15: =COUNTIFS('Action Register'!$K:$K,$J15,'Action Register'!$H:$H,"Critical",'Action Register'!$G:$G,"<>Closed",'Action Register'!$G:$G,"<>Completed",'Action Register'!$G:$G,"<>Cancelled",'Action Register'!$G:$G,"<>Deferred") -> 0 | N15: =COUNTIFS('Action Register'!$K:$K,$J15,'Action Register'!$H:$H,"High",'Action Register'!$G:$G,"<>Closed",'Action Register'!$G:$G,"<>Completed",'Action Register'!$G:$G,"<>Cancelled",'Action Register'!$G:$G,"<>Deferred") -> 0 | O15: =COUNTIFS('Action Register'!$K:$K,$J15,'Action Register'!$J:$J,"High",'Action Register'!$G:$G,"<>Closed",'Action Register'!$G:$G,"<>Completed",'Action Register'!$G:$G,"<>Cancelled",'Action Register'!$G:$G,"<>Deferred") -> 0 | P15: =COUNTIFS('Action Register'!$K:$K,$J15,'Action Register'!$L:$L,"Yes",'Action Register'!$G:$G,"<>Closed",'Action Register'!$G:$G,"<>Completed",'Action Register'!$G:$G,"<>Cancelled",'Action Register'!$G:$G,"<>Deferred") -> 0
A16: Sandy | B16: =COUNTIFS('Action Register'!$D:$D,$A16,'Action Register'!$B:$B,"<>",'Action Register'!$G:$G,"<>Completed",'Action Register'!$G:$G,"<>Cancelled") -> 0 | C16: =COUNTIFS('Action Register'!$D:$D,$A16,'Action Register'!$F:$F,"<"&TODAY(),'Action Register'!$B:$B,"<>",'Action Register'!$G:$G,"<>Closed",'Action Register'!$G:$G,"<>Completed",'Action Register'!$G:$G,"<>Cancelled",'Action Register'!$G:$G,"<>Deferred") -> 0 | D16: =COUNTIFS('Action Register'!$D:$D,$A16,'Action Register'!$H:$H,"Critical",'Action Register'!$G:$G,"<>Closed",'Action Register'!$G:$G,"<>Completed",'Action Register'!$G:$G,"<>Cancelled",'Action Register'!$G:$G,"<>Deferred") -> 0 | E16: =COUNTIFS('Action Register'!$D:$D,$A16,'Action Register'!$H:$H,"High",'Action Register'!$G:$G,"<>Closed",'Action Register'!$G:$G,"<>Completed",'Action Register'!$G:$G,"<>Cancelled",'Action Register'!$G:$G,"<>Deferred") -> 0 | F16: =COUNTIFS('Action Register'!$D:$D,$A16,'Action Register'!$J:$J,"High",'Action Register'!$G:$G,"<>Closed",'Action Register'!$G:$G,"<>Completed",'Action Register'!$G:$G,"<>Cancelled",'Action Register'!$G:$G,"<>Deferred") -> 0 | G16: =COUNTIFS('Action Register'!$D:$D,$A16,'Action Register'!$G:$G,"At Risk")+COUNTIFS('Action Register'!$D:$D,$A16,'Action Register'!$G:$G,"Stuck") -> 0 | H16: =COUNTIFS('Action Register'!$D:$D,$A16,'Action Register'!$L:$L,"Yes",'Action Register'!$G:$G,"<>Closed",'Action Register'!$G:$G,"<>Completed",'Action Register'!$G:$G,"<>Cancelled",'Action Register'!$G:$G,"<>Deferred") -> 0 | J16: Food Safety | K16: =COUNTIFS('Action Register'!$K:$K,$J16,'Action Register'!$B:$B,"<>",'Action Register'!$G:$G,"<>Closed",'Action Register'!$G:$G,"<>Completed",'Action Register'!$G:$G,"<>Cancelled",'Action Register'!$G:$G,"<>Deferred") -> 1 | L16: =COUNTIFS('Action Register'!$K:$K,$J16,'Action Register'!$F:$F,"<"&TODAY(),'Action Register'!$B:$B,"<>",'Action Register'!$G:$G,"<>Closed",'Action Register'!$G:$G,"<>Completed",'Action Register'!$G:$G,"<>Cancelled",'Action Register'!$G:$G,"<>Deferred") -> 0 | M16: =COUNTIFS('Action Register'!$K:$K,$J16,'Action Register'!$H:$H,"Critical",'Action Register'!$G:$G,"<>Closed",'Action Register'!$G:$G,"<>Completed",'Action Register'!$G:$G,"<>Cancelled",'Action Register'!$G:$G,"<>Deferred") -> 0 | N16: =COUNTIFS('Action Register'!$K:$K,$J16,'Action Register'!$H:$H,"High",'Action Register'!$G:$G,"<>Closed",'Action Register'!$G:$G,"<>Completed",'Action Register'!$G:$G,"<>Cancelled",'Action Register'!$G:$G,"<>Deferred") -> 0 | O16: =COUNTIFS('Action Register'!$K:$K,$J16,'Action Register'!$J:$J,"High",'Action Register'!$G:$G,"<>Closed",'Action Register'!$G:$G,"<>Completed",'Action Register'!$G:$G,"<>Cancelled",'Action Register'!$G:$G,"<>Deferred") -> 0 | P16: =COUNTIFS('Action Register'!$K:$K,$J16,'Action Register'!$L:$L,"Yes",'Action Register'!$G:$G,"<>Closed",'Action Register'!$G:$G,"<>Completed",'Action Register'!$G:$G,"<>Cancelled",'Action Register'!$G:$G,"<>Deferred") -> 0
A17: Other | B17: {=SUMPRODUCT(--('Action Register'!$B$5:$B$104<>""),--(COUNTIF($A$10:$A$16,'Action Register'!$D$5:$D$104)=0),--('Action Register'!$G$5:$G$104<>"Closed"),--('Action Register'!$G$5:$G$104<>"Completed"),--('Action Register'!$G$5:$G$104<>"Cancelled"),--('Action Register'!$G$5:$G$104<>"Deferred"))} -> 8 | C17: {=SUMPRODUCT(--('Action Register'!$B$5:$B$104<>""),--(COUNTIF($A$10:$A$16,'Action Register'!$D$5:$D$104)=0),--('Action Register'!$F$5:$F$104<>""),--('Action Register'!$F$5:$F$104<TODAY()),--('Action Register'!$G$5:$G$104<>"Closed"),--('Action Register'!$G$5:$G$104<>"Completed"),--('Action Register'!$G$5:$G$104<>"Cancelled"),--('Action Register'!$G$5:$G$104<>"Deferred"))} -> 1 | D17: {=SUMPRODUCT(--('Action Register'!$B$5:$B$104<>""),--(COUNTIF($A$10:$A$16,'Action Register'!$D$5:$D$104)=0),--('Action Register'!$H$5:$H$104="Critical"),--('Action Register'!$G$5:$G$104<>"Closed"),--('Action Register'!$G$5:$G$104<>"Completed"),--('Action Register'!$G$5:$G$104<>"Cancelled"),--('Action Register'!$G$5:$G$104<>"Deferred"))} -> 0 | E17: {=SUMPRODUCT(--('Action Register'!$B$5:$B$104<>""),--(COUNTIF($A$10:$A$16,'Action Register'!$D$5:$D$104)=0),--('Action Register'!$H$5:$H$104="High"),--('Action Register'!$G$5:$G$104<>"Closed"),--('Action Register'!$G$5:$G$104<>"Completed"),--('Action Register'!$G$5:$G$104<>"Cancelled"),--('Action Register'!$G$5:$G$104<>"Deferred"))} -> 1 | F17: {=SUMPRODUCT(--('Action Register'!$B$5:$B$104<>""),--(COUNTIF($A$10:$A$16,'Action Register'!$D$5:$D$104)=0),--('Action Register'!$J$5:$J$104="High"),--('Action Register'!$G$5:$G$104<>"Closed"),--('Action Register'!$G$5:$G$104<>"Completed"),--('Action Register'!$G$5:$G$104<>"Cancelled"),--('Action Register'!$G$5:$G$104<>"Deferred"))} -> 2 | G17: {=SUMPRODUCT(--('Action Register'!$B$5:$B$104<>""),--(COUNTIF($A$10:$A$16,'Action Register'!$D$5:$D$104)=0),--((('Action Register'!$G$5:$G$104="At Risk")+('Action Register'!$G$5:$G$104="Stuck"))>0))} -> 0 | H17: {=SUMPRODUCT(--('Action Register'!$B$5:$B$104<>""),--(COUNTIF($A$10:$A$16,'Action Register'!$D$5:$D$104)=0),--('Action Register'!$L$5:$L$104="Yes"),--('Action Register'!$G$5:$G$104<>"Closed"),--('Action Register'!$G$5:$G$104<>"Completed"),--('Action Register'!$G$5:$G$104<>"Cancelled"),--('Action Register'!$G$5:$G$104<>"Deferred"))} -> 1 | J17: Commercial Growth | K17: =COUNTIFS('Action Register'!$K:$K,$J17,'Action Register'!$B:$B,"<>",'Action Register'!$G:$G,"<>Closed",'Action Register'!$G:$G,"<>Completed",'Action Register'!$G:$G,"<>Cancelled",'Action Register'!$G:$G,"<>Deferred") -> 3 | L17: =COUNTIFS('Action Register'!$K:$K,$J17,'Action Register'!$F:$F,"<"&TODAY(),'Action Register'!$B:$B,"<>",'Action Register'!$G:$G,"<>Closed",'Action Register'!$G:$G,"<>Completed",'Action Register'!$G:$G,"<>Cancelled",'Action Register'!$G:$G,"<>Deferred") -> 0 | M17: =COUNTIFS('Action Register'!$K:$K,$J17,'Action Register'!$H:$H,"Critical",'Action Register'!$G:$G,"<>Closed",'Action Register'!$G:$G,"<>Completed",'Action Register'!$G:$G,"<>Cancelled",'Action Register'!$G:$G,"<>Deferred") -> 0 | N17: =COUNTIFS('Action Register'!$K:$K,$J17,'Action Register'!$H:$H,"High",'Action Register'!$G:$G,"<>Closed",'Action Register'!$G:$G,"<>Completed",'Action Register'!$G:$G,"<>Cancelled",'Action Register'!$G:$G,"<>Deferred") -> 1 | O17: =COUNTIFS('Action Register'!$K:$K,$J17,'Action Register'!$J:$J,"High",'Action Register'!$G:$G,"<>Closed",'Action Register'!$G:$G,"<>Completed",'Action Register'!$G:$G,"<>Cancelled",'Action Register'!$G:$G,"<>Deferred") -> 1 | P17: =COUNTIFS('Action Register'!$K:$K,$J17,'Action Register'!$L:$L,"Yes",'Action Register'!$G:$G,"<>Closed",'Action Register'!$G:$G,"<>Completed",'Action Register'!$G:$G,"<>Cancelled",'Action Register'!$G:$G,"<>Deferred") -> 0
A18: Executive Summary Charts
A37: Recommended Weekly SLT Review Sequence
A38: 1. Review Critical / High Risk / Escalation items first.
A39: 2. Review ASP Go-Live and Governance & Controls as separate executive categories.
A40: 3. Confirm overdue decisions and items requiring CEO/CFO attention.
A41: 4. Review owner accountability dashboard for bottlenecks.
A42: 5. Move decisions from Decision Queue to Decision Log once made, with follow-up owner and due date.
A44: =NOW() -> 46317.028 | B44: Updated

Sheet Action Register
A1: SLT Action Register
A2: Board-ready action log with priority, risk, strategic alignment, financial impact, escalation, and ASP Go-Live visibility.
A4: SLT Item ID | B4: Item | C4: Category | D4: Owner | E4: Next Action | F4: Due Date | G4: Status | H4: Priority | I4: Flag | J4: Risk Impact | K4: Strategic Objective | L4: Escalation Required | M4: Financial Impact | N4: ASP Readiness Stream | O4: Blocker / Waiting On | P4: Notes | Q4: Date Added | R4: Last Updated | S4: SLT Immutable Key | T4: Active Record
A5: =IF($B5<>"","SLT-"&TEXT(--RIGHT($S5,4),"0000"),"") -> SLT-0001 | B5: Employee Payroll Advances | C5: Human Resources | D5: Gene | E5: Review and refine the draft Payroll Advance Policy and return via Decision Brief for approval by July 20. | F5: 46254 | G5: In Progress | H5: Medium | I5: =IF($H5="Critical","⚑",IF($H5="High","⚑","")) | J5: Medium | K5: Governance | L5: No | M5: Unknown / TBD | N5: N/A | P5: Governance fields added for SLT visibility. | Q5: 46219 | R5: 46219 | S5: SLT-K-0001 | T5: =IF($B5="","",IF(OR($G5="Completed",$G5="Cancelled",$G5="Deferred"),"INACTIVE","ACTIVE")) -> ACTIVE
A6: =IF($B6<>"","SLT-"&TEXT(--RIGHT($S6,4),"0000"),"") -> SLT-0002 | B6: Annual Wage Increase Review and Implementation Plan | C6: Compensation | D6: Gene | E6: Implement approved August increases. Manager communication materials prepared. Review December salary and pay-band alignment strategy in Q4. Item to remain open until approval is finalized and changes are communicated. | F6: 46273 | G6: Completed | H6: High | I6: =IF($H6="Critical","⚑",IF($H6="High","⚑","")) -> ⚑ | J6: Medium | K6: People & Culture | L6: Yes | M6: Unknown / TBD | N6: N/A | P6: Completed September 4, 2026. Letters have been distributed to managers for communication with employees, including 3 salaries eimployees. Sharon Jemima - letter to be provided to Sherry for delivery. Rick Wark and Carol Maia - letters to be provided to Tony to communicate. | Q6: 46219 | R6: 46226 | S6: SLT-K-0002 | T6: =IF($B6="","",IF(OR($G6="Completed",$G6="Cancelled",$G6="Deferred"),"INACTIVE","ACTIVE")) -> INACTIVE
A7: =IF($B7<>"","SLT-"&TEXT(--RIGHT($S7,4),"0000"),"") -> SLT-0003 | B7: ASP Go-Live Executive Readiness Tracker | C7: ASP Go-Live | D7: Maurizio | E7: Create consolidated readiness view covering licensing, construction, operations readiness, HR, training, ERP, capital spend, customer transition and risk register. | F7: 46227 | G7: Cancelled | H7: Low | I7: =IF($H7="Critical","⚑",IF($H7="High","⚑","")) | J7: Low | K7: ASP Go-Live | L7: Yes | M7: >$250K | N7: Operations Readiness | O7: Requires cross-functional inputs | P7: Executive workstream control for ASP Go-Live readiness. | Q7: 46219 | R7: 46219 | S7: SLT-K-0003 | T7: =IF($B7="","",IF(OR($G7="Completed",$G7="Cancelled",$G7="Deferred"),"INACTIVE","ACTIVE")) -> INACTIVE
A8: =IF($B8<>"","SLT-"&TEXT(--RIGHT($S8,4),"0000"),"") -> SLT-0004 | B8: CFO Governance & Controls Register | C8: Governance & Controls | D8: Sherry | E8: Maintain live register of DOA, contract policy, AI governance, incident management, internal audit findings, grant compliance and legal review items. | F8: 46321 | G8: In Progress | H8: Medium | I8: =IF($H8="Critical","⚑",IF($H8="High","⚑","")) | J8: Medium | K8: Governance | L8: Yes | M8: Unknown / TBD | N8: N/A | P8: CFO governance visibility for policies, internal audit, grants, legal review, and controls. | Q8: 46219 | R8: 46219 | S8: SLT-K-0004 | T8: =IF($B8="","",IF(OR($G8="Completed",$G8="Cancelled",$G8="Deferred"),"INACTIVE","ACTIVE")) -> ACTIVE
A9: =IF($B9<>"","SLT-"&TEXT(--RIGHT($S9,4),"0000"),"") -> SLT-0005 | B9: Financial Impact Classification for Open SLT Items | C9: Finance | D9: Dave | E9: Classify open SLT items by estimated financial impact and identify items requiring CFO/CEO review. | F9: 46225 | G9: Completed | H9: High | I9: =IF($H9="Critical","⚑",IF($H9="High","⚑","")) -> ⚑ | J9: High | K9: Cost Reduction | L9: Yes | M9: $50K-$250K | N9: N/A | P9: Financial materiality classification for open SLT items. | Q9: 46219 | R9: 46219 | S9: SLT-K-0005 | T9: =IF($B9="","",IF(OR($G9="Completed",$G9="Cancelled",$G9="Deferred"),"INACTIVE","ACTIVE")) -> INACTIVE
A10: =IF($B10<>"","SLT-"&TEXT(--RIGHT($S10,4),"0000"),"") -> SLT-0006 | B10: Owner Accountability Dashboard Review | C10: Governance & Controls | D10: Sandy | E10: Add owner-level summary of open, overdue and at-risk actions to improve weekly SLT accountability reporting. | F10: 46225 | G10: Completed | H10: High | I10: =IF($H10="Critical","⚑",IF($H10="High","⚑","")) -> ⚑ | J10: Medium | K10: Governance | L10: Yes | M10: Unknown / TBD | N10: N/A | P10: Dashboard control for weekly owner accountability. | Q10: 46219 | R10: 46219 | S10: SLT-K-0006 | T10: =IF($B10="","",IF(OR($G10="Completed",$G10="Cancelled",$G10="Deferred"),"INACTIVE","ACTIVE")) -> INACTIVE
A11: =IF($B11<>"","SLT-"&TEXT(--RIGHT($S11,4),"0000"),"") -> SLT-0007 | B11: ASP Gap Analysis - Ron Judge | C11: ASP Go-Live | D11: Tom | E11: Engaged Ron Judge to formalize scope of work and deliverables to perform the formal readiness and gap assessment. Continue with Practical Approach for: Equipment and maintenance support, maintenance system setup, and remains available to provide targeted support once specific gaps have been identified. | F11: 46251 | G11: Completed | H11: High | I11: =IF($H11="Critical","⚑",IF($H11="High","⚑","")) -> ⚑ | J11: High | K11: ASP Go-Live | L11: Yes | M11: Unknown / TBD | N11: Operations Readiness | P11: Options Considered: Ron Judge, Practical Approach, MNP. Ron Judge presented to SLT on August 17. Action and and ownership teams were assigned and transitioned to the weekly ASP Go-Live meetings for tracking and execution. | Q11: 46225 | R11: 46226 | S11: SLT-K-0007 | T11: =IF($B11="","",IF(OR($G11="Completed",$G11="Cancelled",$G11="Deferred"),"INACTIVE","ACTIVE")) -> INACTIVE
A12: =IF($B12<>"","SLT-"&TEXT(--RIGHT($S12,4),"0000"),"") -> SLT-0008 | B12: Develop a Performance Plan for Tatiana | C12: People & Culture | D12: Adam | E12: Performance plan complete and deliver written operational improvement plan including KPIs, milestones (30/60/90 days), and review checkpoints. Meet with Tatiana by the end of the week, October 9. | F12: 46314 | G12: In Progress | H12: Medium | I12: =IF($H12="Critical","⚑",IF($H12="High","⚑","")) | J12: Medium | K12: People & Culture | L12: No | M12: Unknown / TBD | N12: N/A | Q12: 46226 | R12: 46226 | S12: SLT-K-0008 | T12: =IF($B12="","",IF(OR($G12="Completed",$G12="Cancelled",$G12="Deferred"),"INACTIVE","ACTIVE")) -> ACTIVE
